[2025-04-06T17:13:17.932+0000] {taskinstance.py:1103} INFO - Dependencies all met for dep_context=non-requeueable deps ti=<TaskInstance: great_expectations_validation.validate_data manual__2025-04-06T17:12:59.632075+00:00 [queued]>
[2025-04-06T17:13:17.950+0000] {taskinstance.py:1103} INFO - Dependencies all met for dep_context=requeueable deps ti=<TaskInstance: great_expectations_validation.validate_data manual__2025-04-06T17:12:59.632075+00:00 [queued]>
[2025-04-06T17:13:17.951+0000] {taskinstance.py:1308} INFO - Starting attempt 1 of 4
[2025-04-06T17:13:17.976+0000] {taskinstance.py:1327} INFO - Executing <Task(PythonOperator): validate_data> on 2025-04-06 17:12:59.632075+00:00
[2025-04-06T17:13:17.989+0000] {standard_task_runner.py:57} INFO - Started process 755 to run task
[2025-04-06T17:13:17.994+0000] {standard_task_runner.py:84} INFO - Running: ['***', 'tasks', 'run', 'great_expectations_validation', 'validate_data', 'manual__2025-04-06T17:12:59.632075+00:00', '--job-id', '3', '--raw', '--subdir', 'DAGS_FOLDER/data_validation_dag.py', '--cfg-path', '/tmp/tmphv3n07z3']
[2025-04-06T17:13:17.996+0000] {standard_task_runner.py:85} INFO - Job 3: Subtask validate_data
[2025-04-06T17:13:18.097+0000] {task_command.py:410} INFO - Running <TaskInstance: great_expectations_validation.validate_data manual__2025-04-06T17:12:59.632075+00:00 [running]> on host 6f966d9d4c8d
[2025-04-06T17:13:18.286+0000] {taskinstance.py:1547} INFO - Exporting env vars: AIRFLOW_CTX_DAG_OWNER='***' AIRFLOW_CTX_DAG_ID='great_expectations_validation' AIRFLOW_CTX_TASK_ID='validate_data' AIRFLOW_CTX_EXECUTION_DATE='2025-04-06T17:12:59.632075+00:00' AIRFLOW_CTX_TRY_NUMBER='1' AIRFLOW_CTX_DAG_RUN_ID='manual__2025-04-06T17:12:59.632075+00:00'
[2025-04-06T17:13:18.298+0000] {util.py:2007} INFO - Could not find local context root directory
[2025-04-06T17:13:18.303+0000] {base.py:2134} INFO - Created temporary directory '/tmp/tmpvek9cgul' for ephemeral docs site
[2025-04-06T17:13:18.309+0000] {abstract_data_context.py:5575} INFO - EphemeralDataContext has not implemented `_load_fluent_config()` returning empty `GxConfig`
[2025-04-06T17:13:18.311+0000] {config.py:185} INFO - Loading 'datasources' ->
[]
[2025-04-06T17:13:18.472+0000] {fluent_base_model.py:257} INFO - PostgresDatasource.dict() - substituting config values
[2025-04-06T17:13:18.549+0000] {logging_mixin.py:150} INFO - postgresql://sportadvantagehr:sportpassword@business-postgres:5432/sportadvantages
[2025-04-06T17:13:18.556+0000] {taskinstance.py:1824} ERROR - Task failed with exception
Traceback (most recent call last):
  File "/home/airflow/.local/lib/python3.7/site-packages/airflow/operators/python.py", line 181, in execute
    return_value = self.execute_callable()
  File "/home/airflow/.local/lib/python3.7/site-packages/airflow/operators/python.py", line 198, in execute_callable
    return self.python_callable(*self.op_args, **self.op_kwargs)
  File "/opt/airflow/dags/data_validation_dag.py", line 119, in run_ge_validation
    name="sport_activities", table_name="sport_advantages.sport_activities"
  File "/home/airflow/.local/lib/python3.7/site-packages/great_expectations/datasource/fluent/sql_datasource.py", line 991, in add_table_asset
    return self._add_asset(asset)
  File "/home/airflow/.local/lib/python3.7/site-packages/great_expectations/datasource/fluent/interfaces.py", line 546, in _add_asset
    asset.test_connection()
  File "/home/airflow/.local/lib/python3.7/site-packages/great_expectations/datasource/fluent/sql_datasource.py", line 834, in test_connection
    f'Attempt to connect to table: "{self.qualified_name}" failed because the table '
great_expectations.datasource.fluent.interfaces.TestConnectionError: Attempt to connect to table: "sport_advantages.sport_activities" failed because the table "sport_advantages.sport_activities" does not exist.
[2025-04-06T17:13:18.617+0000] {taskinstance.py:1350} INFO - Marking task as UP_FOR_RETRY. dag_id=great_expectations_validation, task_id=validate_data, execution_date=20250406T171259, start_date=20250406T171317, end_date=20250406T171318
[2025-04-06T17:13:18.651+0000] {standard_task_runner.py:109} ERROR - Failed to execute job 3 for task validate_data (Attempt to connect to table: "sport_advantages.sport_activities" failed because the table "sport_advantages.sport_activities" does not exist.; 755)
[2025-04-06T17:13:18.691+0000] {local_task_job_runner.py:225} INFO - Task exited with return code 1
[2025-04-06T17:13:18.729+0000] {taskinstance.py:2653} INFO - 0 downstream tasks scheduled from follow-on schedule check
