[2025-04-06T16:36:18.907+0000] {taskinstance.py:1103} INFO - Dependencies all met for dep_context=non-requeueable deps ti=<TaskInstance: great_expectations_validation.validate_data manual__2025-04-06T16:36:11.406102+00:00 [queued]>
[2025-04-06T16:36:18.921+0000] {taskinstance.py:1103} INFO - Dependencies all met for dep_context=requeueable deps ti=<TaskInstance: great_expectations_validation.validate_data manual__2025-04-06T16:36:11.406102+00:00 [queued]>
[2025-04-06T16:36:18.922+0000] {taskinstance.py:1308} INFO - Starting attempt 1 of 1
[2025-04-06T16:36:18.948+0000] {taskinstance.py:1327} INFO - Executing <Task(PythonOperator): validate_data> on 2025-04-06 16:36:11.406102+00:00
[2025-04-06T16:36:18.961+0000] {standard_task_runner.py:57} INFO - Started process 252 to run task
[2025-04-06T16:36:18.966+0000] {standard_task_runner.py:84} INFO - Running: ['***', 'tasks', 'run', 'great_expectations_validation', 'validate_data', 'manual__2025-04-06T16:36:11.406102+00:00', '--job-id', '2', '--raw', '--subdir', 'DAGS_FOLDER/data_validation_dag.py', '--cfg-path', '/tmp/tmpmkxsc81d']
[2025-04-06T16:36:18.969+0000] {standard_task_runner.py:85} INFO - Job 2: Subtask validate_data
[2025-04-06T16:36:19.061+0000] {task_command.py:410} INFO - Running <TaskInstance: great_expectations_validation.validate_data manual__2025-04-06T16:36:11.406102+00:00 [running]> on host 335c205a3d40
[2025-04-06T16:36:19.228+0000] {taskinstance.py:1547} INFO - Exporting env vars: AIRFLOW_CTX_DAG_OWNER='***' AIRFLOW_CTX_DAG_ID='great_expectations_validation' AIRFLOW_CTX_TASK_ID='validate_data' AIRFLOW_CTX_EXECUTION_DATE='2025-04-06T16:36:11.406102+00:00' AIRFLOW_CTX_TRY_NUMBER='1' AIRFLOW_CTX_DAG_RUN_ID='manual__2025-04-06T16:36:11.406102+00:00'
[2025-04-06T16:36:19.233+0000] {util.py:2007} INFO - Could not find local context root directory
[2025-04-06T16:36:19.234+0000] {base.py:2134} INFO - Created temporary directory '/tmp/tmp6etj9i1p' for ephemeral docs site
[2025-04-06T16:36:19.238+0000] {abstract_data_context.py:5575} INFO - EphemeralDataContext has not implemented `_load_fluent_config()` returning empty `GxConfig`
[2025-04-06T16:36:19.239+0000] {config.py:185} INFO - Loading 'datasources' ->
[]
[2025-04-06T16:36:19.395+0000] {fluent_base_model.py:257} INFO - PostgresDatasource.dict() - substituting config values
[2025-04-06T16:36:19.448+0000] {taskinstance.py:1824} ERROR - Task failed with exception
Traceback (most recent call last):
  File "/home/airflow/.local/lib/python3.7/site-packages/airflow/operators/python.py", line 181, in execute
    return_value = self.execute_callable()
  File "/home/airflow/.local/lib/python3.7/site-packages/airflow/operators/python.py", line 198, in execute_callable
    return self.python_callable(*self.op_args, **self.op_kwargs)
  File "/opt/airflow/dags/data_validation_dag.py", line 32, in run_ge_validation
    name="sport_activities", table_name="sport_advantages.sport_activities"
  File "/home/airflow/.local/lib/python3.7/site-packages/great_expectations/datasource/fluent/sql_datasource.py", line 991, in add_table_asset
    return self._add_asset(asset)
  File "/home/airflow/.local/lib/python3.7/site-packages/great_expectations/datasource/fluent/interfaces.py", line 546, in _add_asset
    asset.test_connection()
  File "/home/airflow/.local/lib/python3.7/site-packages/great_expectations/datasource/fluent/sql_datasource.py", line 834, in test_connection
    f'Attempt to connect to table: "{self.qualified_name}" failed because the table '
great_expectations.datasource.fluent.interfaces.TestConnectionError: Attempt to connect to table: "sport_advantages.sport_activities" failed because the table "sport_advantages.sport_activities" does not exist.
[2025-04-06T16:36:19.467+0000] {taskinstance.py:1350} INFO - Marking task as FAILED. dag_id=great_expectations_validation, task_id=validate_data, execution_date=20250406T163611, start_date=20250406T163618, end_date=20250406T163619
[2025-04-06T16:36:19.485+0000] {standard_task_runner.py:109} ERROR - Failed to execute job 2 for task validate_data (Attempt to connect to table: "sport_advantages.sport_activities" failed because the table "sport_advantages.sport_activities" does not exist.; 252)
[2025-04-06T16:36:19.541+0000] {local_task_job_runner.py:225} INFO - Task exited with return code 1
[2025-04-06T16:36:19.573+0000] {taskinstance.py:2653} INFO - 0 downstream tasks scheduled from follow-on schedule check
